Traceback (most recent call last):
  File "/opt/anaconda3/envs/causality_lab/lib/python3.10/site-packages/jupyter_cache/executors/utils.py", line 58, in single_nb_execution
    executenb(
  File "/opt/anaconda3/envs/causality_lab/lib/python3.10/site-packages/nbclient/client.py", line 1314, in execute
    return NotebookClient(nb=nb, resources=resources, km=km, **kwargs).execute()
  File "/opt/anaconda3/envs/causality_lab/lib/python3.10/site-packages/jupyter_core/utils/__init__.py", line 165, in wrapped
    return loop.run_until_complete(inner)
  File "/opt/anaconda3/envs/causality_lab/lib/python3.10/asyncio/base_events.py", line 646, in run_until_complete
    return future.result()
  File "/opt/anaconda3/envs/causality_lab/lib/python3.10/site-packages/nbclient/client.py", line 709, in async_execute
    await self.async_execute_cell(
  File "/opt/anaconda3/envs/causality_lab/lib/python3.10/site-packages/nbclient/client.py", line 1062, in async_execute_cell
    await self._check_raise_for_error(cell, cell_index, exec_reply)
  File "/opt/anaconda3/envs/causality_lab/lib/python3.10/site-packages/nbclient/client.py", line 918, in _check_raise_for_error
    raise CellExecutionError.from_cell_and_msg(cell, exec_reply_content)
nbclient.exceptions.CellExecutionError: An error occurred while executing the following cell:
------------------
import numpy as np
import matplotlib.pyplot as plt
from sklearn.model_selection import train_test_split
import xgboost as xgb

# Generate synthetic data
np.random.seed(42)
X = np.random.rand(100, 5)
y = X @ [1.5, -2, 0, 3.5, -1] + np.random.randn(100) * 0.1

# Split data into training and test sets
X_train, X_test, y_train, y_test = train_test_split(X, y, test_size=0.2, random_state=42)

# Convert the data into DMatrix format for XGBoost
train_dmatrix = xgb.DMatrix(X_train, label=y_train)
test_dmatrix = xgb.DMatrix(X_test, label=y_test)

# Define the model parameters
params = {
    "objective": "reg:squarederror",
    "max_depth": 3,
    "eta": 0.1,
    "eval_metric": "rmse"
}

# Train the XGBoost model with evaluation sets
evals = [(train_dmatrix, 'train'), (test_dmatrix, 'test')]
num_rounds = 100
evals_result = {}
xg_reg = xgb.train(params, train_dmatrix, num_boost_round=num_rounds, evals=evals, evals_result=evals_result, verbose_eval=False)

# Plot the evaluation results
epochs = len(evals_result['train']['rmse'])
x_axis = range(0, epochs)
plt.figure(figsize=(10, 4))
plt.plot(x_axis, evals_result['train']['rmse'], label='Train', lw=3, c='c')
plt.plot(x_axis, evals_result['test']['rmse'], label='Test', lw=3, c='m')
plt.xlabel('Boosting Round')
plt.ylabel('RMSE')
plt.title('XGBoost Training and Test RMSE')
plt.legend()
plt.show()

------------------


[0;31m---------------------------------------------------------------------------[0m
[0;31mModuleNotFoundError[0m                       Traceback (most recent call last)
Cell [0;32mIn[5], line 4[0m
[1;32m      2[0m [38;5;28;01mimport[39;00m [38;5;21;01mmatplotlib[39;00m[38;5;21;01m.[39;00m[38;5;21;01mpyplot[39;00m [38;5;28;01mas[39;00m [38;5;21;01mplt[39;00m
[1;32m      3[0m [38;5;28;01mfrom[39;00m [38;5;21;01msklearn[39;00m[38;5;21;01m.[39;00m[38;5;21;01mmodel_selection[39;00m [38;5;28;01mimport[39;00m train_test_split
[0;32m----> 4[0m [38;5;28;01mimport[39;00m [38;5;21;01mxgboost[39;00m [38;5;28;01mas[39;00m [38;5;21;01mxgb[39;00m
[1;32m      6[0m [38;5;66;03m# Generate synthetic data[39;00m
[1;32m      7[0m np[38;5;241m.[39mrandom[38;5;241m.[39mseed([38;5;241m42[39m)

[0;31mModuleNotFoundError[0m: No module named 'xgboost'

