Traceback (most recent call last):
  File "/opt/anaconda3/envs/causality_lab/lib/python3.10/site-packages/jupyter_cache/executors/utils.py", line 58, in single_nb_execution
    executenb(
  File "/opt/anaconda3/envs/causality_lab/lib/python3.10/site-packages/nbclient/client.py", line 1314, in execute
    return NotebookClient(nb=nb, resources=resources, km=km, **kwargs).execute()
  File "/opt/anaconda3/envs/causality_lab/lib/python3.10/site-packages/jupyter_core/utils/__init__.py", line 165, in wrapped
    return loop.run_until_complete(inner)
  File "/opt/anaconda3/envs/causality_lab/lib/python3.10/asyncio/base_events.py", line 646, in run_until_complete
    return future.result()
  File "/opt/anaconda3/envs/causality_lab/lib/python3.10/site-packages/nbclient/client.py", line 709, in async_execute
    await self.async_execute_cell(
  File "/opt/anaconda3/envs/causality_lab/lib/python3.10/site-packages/nbclient/client.py", line 1062, in async_execute_cell
    await self._check_raise_for_error(cell, cell_index, exec_reply)
  File "/opt/anaconda3/envs/causality_lab/lib/python3.10/site-packages/nbclient/client.py", line 918, in _check_raise_for_error
    raise CellExecutionError.from_cell_and_msg(cell, exec_reply_content)
nbclient.exceptions.CellExecutionError: An error occurred while executing the following cell:
------------------
ica = FastICA(n_components=2)
recovered_signals = ica.fit_transform(X)  # Reconstruct signals
plt.figure(figsize=(12, 4))
plt.plot(time, recovered_signals)
------------------


[0;31m---------------------------------------------------------------------------[0m
[0;31mNameError[0m                                 Traceback (most recent call last)
Cell [0;32mIn[4], line 1[0m
[0;32m----> 1[0m ica [38;5;241m=[39m [43mFastICA[49m(n_components[38;5;241m=[39m[38;5;241m2[39m)
[1;32m      2[0m recovered_signals [38;5;241m=[39m ica[38;5;241m.[39mfit_transform(X)  [38;5;66;03m# Reconstruct signals[39;00m
[1;32m      3[0m plt[38;5;241m.[39mfigure(figsize[38;5;241m=[39m([38;5;241m12[39m, [38;5;241m4[39m))

[0;31mNameError[0m: name 'FastICA' is not defined

