Traceback (most recent call last):
  File "/opt/anaconda3/envs/causality_lab/lib/python3.10/site-packages/nbclient/client.py", line 782, in _async_poll_for_reply
    msg = await ensure_async(self.kc.shell_channel.get_msg(timeout=new_timeout))
  File "/opt/anaconda3/envs/causality_lab/lib/python3.10/site-packages/jupyter_core/utils/__init__.py", line 198, in ensure_async
    result = await obj
  File "/opt/anaconda3/envs/causality_lab/lib/python3.10/site-packages/jupyter_client/channels.py", line 230, in get_msg
    raise Empty
_queue.Empty

During handling of the above exception, another exception occurred:

Traceback (most recent call last):
  File "/opt/anaconda3/envs/causality_lab/lib/python3.10/site-packages/jupyter_cache/executors/utils.py", line 58, in single_nb_execution
    executenb(
  File "/opt/anaconda3/envs/causality_lab/lib/python3.10/site-packages/nbclient/client.py", line 1314, in execute
    return NotebookClient(nb=nb, resources=resources, km=km, **kwargs).execute()
  File "/opt/anaconda3/envs/causality_lab/lib/python3.10/site-packages/jupyter_core/utils/__init__.py", line 165, in wrapped
    return loop.run_until_complete(inner)
  File "/opt/anaconda3/envs/causality_lab/lib/python3.10/asyncio/base_events.py", line 646, in run_until_complete
    return future.result()
  File "/opt/anaconda3/envs/causality_lab/lib/python3.10/site-packages/nbclient/client.py", line 709, in async_execute
    await self.async_execute_cell(
  File "/opt/anaconda3/envs/causality_lab/lib/python3.10/site-packages/nbclient/client.py", line 1005, in async_execute_cell
    exec_reply = await self.task_poll_for_reply
  File "/opt/anaconda3/envs/causality_lab/lib/python3.10/site-packages/nbclient/client.py", line 806, in _async_poll_for_reply
    error_on_timeout_execute_reply = await self._async_handle_timeout(timeout, cell)
  File "/opt/anaconda3/envs/causality_lab/lib/python3.10/site-packages/nbclient/client.py", line 856, in _async_handle_timeout
    raise CellTimeoutError.error_from_timeout_and_cell(
nbclient.exceptions.CellTimeoutError: A cell timed out while it was being executed, after 30 seconds.
The message was: Cell execution timed out.
Here is a preview of the cell contents:
-------------------
['# Run the simulation', 'variances_active_runs, variances_random_runs = run_active_learning_simulation_with_data_regeneration(n_runs=50, n_iterations=50)', '', '# Compute means and confidence intervals', 'mean_variances_active = np.mean(variances_active_runs, axis=0)']
...
["plt.fill_between(range(n_iterations), ci_variances_random_5, ci_variances_random_95, color='orange', alpha=0.2)", "plt.xlabel('Iteration')", "plt.ylabel('Average Variance of Coefficients')", 'plt.legend()', 'plt.show()']
-------------------

