Traceback (most recent call last):
  File "/opt/anaconda3/envs/causal-inference-book/lib/python3.11/site-packages/jupyter_cache/executors/utils.py", line 58, in single_nb_execution
    executenb(
  File "/opt/anaconda3/envs/causal-inference-book/lib/python3.11/site-packages/nbclient/client.py", line 1305, in execute
    return NotebookClient(nb=nb, resources=resources, km=km, **kwargs).execute()
           ^^^^^^^^^^^^^^^^^^^^^^^^^^^^^^^^^^^^^^^^^^^^^^^^^^^^^^^^^^^^^^^^^^^^^
  File "/opt/anaconda3/envs/causal-inference-book/lib/python3.11/site-packages/jupyter_core/utils/__init__.py", line 173, in wrapped
    return loop.run_until_complete(inner)
           ^^^^^^^^^^^^^^^^^^^^^^^^^^^^^^
  File "/opt/anaconda3/envs/causal-inference-book/lib/python3.11/asyncio/base_events.py", line 654, in run_until_complete
    return future.result()
           ^^^^^^^^^^^^^^^
  File "/opt/anaconda3/envs/causal-inference-book/lib/python3.11/site-packages/nbclient/client.py", line 705, in async_execute
    await self.async_execute_cell(
  File "/opt/anaconda3/envs/causal-inference-book/lib/python3.11/site-packages/nbclient/client.py", line 1058, in async_execute_cell
    await self._check_raise_for_error(cell, cell_index, exec_reply)
  File "/opt/anaconda3/envs/causal-inference-book/lib/python3.11/site-packages/nbclient/client.py", line 914, in _check_raise_for_error
    raise CellExecutionError.from_cell_and_msg(cell, exec_reply_content)
nbclient.exceptions.CellExecutionError: An error occurred while executing the following cell:
------------------
import pandas as pd
import matplotlib.pyplot as plt
%matplotlib inline
import seaborn as sns

# Setting a random seed for reproducibility
np.random.seed(42)

# Generating synthetic data
n = 100000
temperatures = np.random.normal(20, 5, n)  # average temperature in Celsius
electricity_load = 0.2 * (temperatures - 20)**2 + 70 + np.random.normal(0, 5, n)  # Quadratic relationship for U-shape
ice_cream_sales = 5* temperatures + np.random.normal(0, 20, n)  # also influenced by temperature

# Creating a DataFrame
data = pd.DataFrame({'Temperature': temperatures, 'Electricity Load': electricity_load, 'Ice Cream Sales': ice_cream_sales})

# Setting up the plots
fig, axes = plt.subplots(1, 3, figsize=(18, 5))

# Temperature vs Electricity Load with hexbin plot
hb1 = axes[0].hexbin(data['Temperature'], data['Electricity Load'], gridsize=50, cmap='Blues', bins='log')
axes[0].set_title('Temperature vs Electricity Load')
axes[0].set_xlabel('Temperature (Â°C)')
axes[0].set_ylabel('Electricity Load (MW)')

# Temperature vs Ice Cream Sales with hexbin plot
hb2 = axes[1].hexbin(data['Temperature'], data['Ice Cream Sales'], gridsize=50, cmap='Blues', bins='log')
axes[1].set_title('Temperature vs Ice Cream Sales')
axes[1].set_xlabel('Temperature (Â°C)')
axes[1].set_ylabel('Ice Cream Sales (GBP)')

# Electricity Load vs Ice Cream Sales with hexbin plot
hb3 = axes[2].hexbin(data['Electricity Load'], data['Ice Cream Sales'], gridsize=50, cmap='Blues', bins='log')
axes[2].set_title('Electricity Load vs Ice Cream Sales')
axes[2].set_xlabel('Electricity Load (MW)')
axes[2].set_ylabel('Ice Cream Sales (GBP)')
------------------


[0;31m---------------------------------------------------------------------------[0m
[0;31mNameError[0m                                 Traceback (most recent call last)
Cell [0;32mIn[2], line 7[0m
[1;32m      4[0m [38;5;28;01mimport[39;00m [38;5;21;01mseaborn[39;00m [38;5;28;01mas[39;00m [38;5;21;01msns[39;00m
[1;32m      6[0m [38;5;66;03m# Setting a random seed for reproducibility[39;00m
[0;32m----> 7[0m np[38;5;241m.[39mrandom[38;5;241m.[39mseed([38;5;241m42[39m)
[1;32m      9[0m [38;5;66;03m# Generating synthetic data[39;00m
[1;32m     10[0m n [38;5;241m=[39m [38;5;241m100000[39m

[0;31mNameError[0m: name 'np' is not defined

