Traceback (most recent call last):
  File "/opt/anaconda3/envs/causal-inference-book/lib/python3.11/site-packages/jupyter_cache/executors/utils.py", line 58, in single_nb_execution
    executenb(
  File "/opt/anaconda3/envs/causal-inference-book/lib/python3.11/site-packages/nbclient/client.py", line 1305, in execute
    return NotebookClient(nb=nb, resources=resources, km=km, **kwargs).execute()
           ^^^^^^^^^^^^^^^^^^^^^^^^^^^^^^^^^^^^^^^^^^^^^^^^^^^^^^^^^^^^^^^^^^^^^
  File "/opt/anaconda3/envs/causal-inference-book/lib/python3.11/site-packages/jupyter_core/utils/__init__.py", line 173, in wrapped
    return loop.run_until_complete(inner)
           ^^^^^^^^^^^^^^^^^^^^^^^^^^^^^^
  File "/opt/anaconda3/envs/causal-inference-book/lib/python3.11/asyncio/base_events.py", line 654, in run_until_complete
    return future.result()
           ^^^^^^^^^^^^^^^
  File "/opt/anaconda3/envs/causal-inference-book/lib/python3.11/site-packages/nbclient/client.py", line 705, in async_execute
    await self.async_execute_cell(
  File "/opt/anaconda3/envs/causal-inference-book/lib/python3.11/site-packages/nbclient/client.py", line 1058, in async_execute_cell
    await self._check_raise_for_error(cell, cell_index, exec_reply)
  File "/opt/anaconda3/envs/causal-inference-book/lib/python3.11/site-packages/nbclient/client.py", line 914, in _check_raise_for_error
    raise CellExecutionError.from_cell_and_msg(cell, exec_reply_content)
nbclient.exceptions.CellExecutionError: An error occurred while executing the following cell:
------------------
import xgboost as xgb
from sklearn.metrics import mean_squared_error

# Generate synthetic data
X, y = make_reg

ression(n_samples=100, n_features=1, noise=0.1, random_state=42)

# Split dataset
X_train, X_test, y_train, y_test = train_test_split(X, y, test_size=0.3, random_state=42)

# Train XGBoost model
xgb_reg = xgb.XGBRegressor(objective='reg:squarederror', n_estimators=100)
xgb_reg.fit(X_train, y_train)

# Predict and evaluate
y_pred = xgb_reg.predict(X_test)
mse = mean_squared_error(y_test, y_pred)
print(f"MSE: {mse}")

# Plotting
X_grid = np.linspace(min(X), max(X), 100).reshape(-1, 1)
y_grid_pred = xgb_reg.predict(X_grid)

plt.figure(figsize=(10, 6))
plt.scatter(X, y, label='Data')
plt.plot(X_grid, y_grid_pred, color='red', label='XGBoost Prediction')
plt.title('XGBoost Regression')
plt.xlabel('X')
plt.ylabel('y')
plt.legend()
plt.show()
------------------


[0;31m---------------------------------------------------------------------------[0m
[0;31mNameError[0m                                 Traceback (most recent call last)
Cell [0;32mIn[6], line 5[0m
[1;32m      2[0m [38;5;28;01mfrom[39;00m [38;5;21;01msklearn[39;00m[38;5;21;01m.[39;00m[38;5;21;01mmetrics[39;00m [38;5;28;01mimport[39;00m mean_squared_error
[1;32m      4[0m [38;5;66;03m# Generate synthetic data[39;00m
[0;32m----> 5[0m X, y [38;5;241m=[39m make_reg
[1;32m      7[0m ression(n_samples[38;5;241m=[39m[38;5;241m100[39m, n_features[38;5;241m=[39m[38;5;241m1[39m, noise[38;5;241m=[39m[38;5;241m0.1[39m, random_state[38;5;241m=[39m[38;5;241m42[39m)
[1;32m      9[0m [38;5;66;03m# Split dataset[39;00m

[0;31mNameError[0m: name 'make_reg' is not defined

